Workbook
Name _edn1: 'MoSCoW Method'!$A$1126
Name _edn2: 'MoSCoW Method'!$A$1127
Name _ednref1: 'MoSCoW Method'!#REF!
Name _ednref2: 'MoSCoW Method'!$D$35

Sheet MoSCoW Method
A1: This tool is designed to help prioritize UX aspects for mobile applications. You'll use it to rank the UX aspects for assessing your mobile app in your organization. Stage-1: Use the MoSCoW Method to assign one of the below categories in the blue cells for each aspect, considering these four criteria: 1-User profiles: Importance of this aspect for the different user groups of the mobile app.. 2-App domain specificity: The relevance of this aspect to the mobile application domain will be developed or evaluated. 3-Task complexity: Importance of this aspect for assessing complex tasks. 4-Feasibility: Feasibility of implementing this aspect given available resources (time, cost, personnel). MoSCoW Method categories: -Must Have: Essential UX aspects critical for the app's functionality and user satisfaction. Necessary for meeting basic user needs. -Should Have: Important aspects that enhance UX but aren't critical. -Could Have: Nice-to-have features that improve UX but are non-essential. -Won't Have: Aspects that won't be included due to irrelevance, low impact, or constraints.
A2: Domain:
A3: Mobile UX Aspects Taxonomy | D3: MoSCoW Method
A4: NO. | B4: Element | C4: Definition | D4: User profiles | E4: App domain specificity | F4: Task Complexity | G4: Feasibility | H4: Decision | I4: Final aspects
A5: User-Centric Dimension
A6: 1 | B6: Usability | C6: The extent to which specified users can use a product to achieve specified goals with effectiveness, efficiency, satisfaction, understandability, learnability, operability, etc, in a specified context of use. | H6: =IF(COUNTIF(D6:G6, "Must have")>0, "Must have", IF(COUNTIF(D6:G6, "Should have")>0, "Should have", IF(COUNTIF(D6:G6, "Could have")>0, "Could have", IF(COUNTIF(D6:G6, "Won’t have")>0, "Won’t have", "-")))) -> - | I6: =IF(OR(ISNUMBER(SEARCH("Must have",H6)),ISNUMBER(SEARCH("Should have",H6))),B6,"")
A7: 2 | B7: Emotional | C7: The full spectrum of desirable feelings users experiences while interacting with a product or service. These emotions are influenced by the context and goals of the interaction, contributing to a pleasurable and engaging product experience. | H7: =IF(COUNTIF(D7:G7, "Must have")>0, "Must have", IF(COUNTIF(D7:G7, "Should have")>0, "Should have", IF(COUNTIF(D7:G7, "Could have")>0, "Could have", IF(COUNTIF(D7:G7, "Won’t have")>0, "Won’t have", "-")))) -> - | I7: =IF(OR(ISNUMBER(SEARCH("Must have",H7)),ISNUMBER(SEARCH("Should have",H7))),B7,"")
A8: 3 | B8: External Subjective Factors | C8: Refer to user-related, external factors that indirectly influence the user experience (UX) by shaping a user's perception, attitudes, and sensations toward a product or service. Unlike internal subjective factors (emotions, motivations), these factors arise from the user's experiences and beliefs. | H8: =IF(COUNTIF(D8:G8, "Must have")>0, "Must have", IF(COUNTIF(D8:G8, "Should have")>0, "Should have", IF(COUNTIF(D8:G8, "Could have")>0, "Could have", IF(COUNTIF(D8:G8, "Won’t have")>0, "Won’t have", "-")))) -> - | I8: =IF(OR(ISNUMBER(SEARCH("Must have",H8)),ISNUMBER(SEARCH("Should have",H8))),B8,"")
A9: 4 | B9: Engagement | C9: The level of involvement, interest, and enthusiasm a user has with a product or service involves capturing attention, encouraging participation, and fostering a meaningful connection. | H9: =IF(COUNTIF(D9:G9, "Must have")>0, "Must have", IF(COUNTIF(D9:G9, "Should have")>0, "Should have", IF(COUNTIF(D9:G9, "Could have")>0, "Could have", IF(COUNTIF(D9:G9, "Won’t have")>0, "Won’t have", "-")))) -> - | I9: =IF(OR(ISNUMBER(SEARCH("Must have",H9)),ISNUMBER(SEARCH("Should have",H9))),B9,"")
A10: 5 | B10: Stimulation | C10: Refers to interactive features and elements within an app that captivate users by piquing their curiosity, generating interest, and fostering enjoyment. Unlike engagement, it aims to provoke immediate exploration through novel functionalities, creative activities, or problem-solving opportunities. It encourages users to actively interact with the app, discover new aspects, and potentially gain new insights or experiences. | H10: =IF(COUNTIF(D10:G10, "Must have")>0, "Must have", IF(COUNTIF(D10:G10, "Should have")>0, "Should have", IF(COUNTIF(D10:G10, "Could have")>0, "Could have", IF(COUNTIF(D10:G10, "Won’t have")>0, "Won’t have", "-")))) -> - | I10: =IF(OR(ISNUMBER(SEARCH("Must have",H10)),ISNUMBER(SEARCH("Should have",H10))),B10,"")
A11: 6 | B11: Effort | C11: Refers to the cognitive and physical exertion users require to interact with a mobile application. Minimizing effort by providing intuitive interfaces, streamlined processes, and clear feedback enhances the overall user experience, satisfaction, and retention. | H11: =IF(COUNTIF(D11:G11, "Must have")>0, "Must have", IF(COUNTIF(D11:G11, "Should have")>0, "Should have", IF(COUNTIF(D11:G11, "Could have")>0, "Could have", IF(COUNTIF(D11:G11, "Won’t have")>0, "Won’t have", "-")))) -> - | I11: =IF(OR(ISNUMBER(SEARCH("Must have",H11)),ISNUMBER(SEARCH("Should have",H11))),B11,"")
A12: 7 | B12: Desirability | C12: The ability of a product or service, through its visual appeal, emotional resonance, and alignment with user preferences, to evoke a strong desire or attraction among its target audience. | H12: =IF(COUNTIF(D12:G12, "Must have")>0, "Must have", IF(COUNTIF(D12:G12, "Should have")>0, "Should have", IF(COUNTIF(D12:G12, "Could have")>0, "Could have", IF(COUNTIF(D12:G12, "Won’t have")>0, "Won’t have", "-")))) -> - | I12: =IF(OR(ISNUMBER(SEARCH("Must have",H12)),ISNUMBER(SEARCH("Should have",H12))),B12,"")
A13: 8 | B13: Valuable | C13: Ensuring the app provides significant value to users by addressing their needs, solving their problems, or enhancing their lives. This aspect goes beyond mere functionality, encompassing all elements of UX design to deliver holistic user value. It focuses on the overall benefits and improvements the app brings to users, encouraging their appreciation and satisfaction with the product. | H13: =IF(COUNTIF(D13:G13, "Must have")>0, "Must have", IF(COUNTIF(D13:G13, "Should have")>0, "Should have", IF(COUNTIF(D13:G13, "Could have")>0, "Could have", IF(COUNTIF(D13:G13, "Won’t have")>0, "Won’t have", "-")))) -> - | I13: =IF(OR(ISNUMBER(SEARCH("Must have",H13)),ISNUMBER(SEARCH("Should have",H13))),B13,"")
A14: App-Centric Dimension
A15: 9 | B15: Functionality | C15: An app's features and capabilities ensure the product is fully operational and aligns with user objectives. | H15: =IF(COUNTIF(D15:G15, "Must have")>0, "Must have", IF(COUNTIF(D15:G15, "Should have")>0, "Should have", IF(COUNTIF(D15:G15, "Could have")>0, "Could have", IF(COUNTIF(D15:G15, "Won’t have")>0, "Won’t have", "-")))) -> - | I15: =IF(OR(ISNUMBER(SEARCH("Must have",H15)),ISNUMBER(SEARCH("Should have",H15))),B15,"")
A16: 10 | B16: Aesthetic Design | C16: The visual harmony, appeal, and inherent beauty of the product colors, texts, grapgics, layout, audio, etc. | H16: =IF(COUNTIF(D16:G16, "Must have")>0, "Must have", IF(COUNTIF(D16:G16, "Should have")>0, "Should have", IF(COUNTIF(D16:G16, "Could have")>0, "Could have", IF(COUNTIF(D16:G16, "Won’t have")>0, "Won’t have", "-")))) -> - | I16: =IF(OR(ISNUMBER(SEARCH("Must have",H16)),ISNUMBER(SEARCH("Should have",H16))),B16,"")
A17: 11 | B17: Safety | C17: The extent to which the app mitigates the risk of harm to individuals or other resources, including hardware and stored information, within a defined use context. | H17: =IF(COUNTIF(D17:G17, "Must have")>0, "Must have", IF(COUNTIF(D17:G17, "Should have")>0, "Should have", IF(COUNTIF(D17:G17, "Could have")>0, "Could have", IF(COUNTIF(D17:G17, "Won’t have")>0, "Won’t have", "-")))) -> - | I17: =IF(OR(ISNUMBER(SEARCH("Must have",H17)),ISNUMBER(SEARCH("Should have",H17))),B17,"")
A18: 12 | B18: External Application Assistants | C18: Refer to tools or technical checkers external to the app itself that aid users in verifying compatibility with their devices (such as mobile phones and tablets) and operating systems (like Android and iOS). They also assist in troubleshooting technical issues related to requirements such as internet speed. | H18: =IF(COUNTIF(D18:G18, "Must have")>0, "Must have", IF(COUNTIF(D18:G18, "Should have")>0, "Should have", IF(COUNTIF(D18:G18, "Could have")>0, "Could have", IF(COUNTIF(D18:G18, "Won’t have")>0, "Won’t have", "-")))) -> - | I18: =IF(OR(ISNUMBER(SEARCH("Must have",H18)),ISNUMBER(SEARCH("Should have",H18))),B18,"")
A19: 13 | B19: Novelty | C19: Novelty entails introducing new and original elements or features compared to existing ones. It reflects the product's level of innovation and creativity, influencing its ability to attract user interest and engagement. | H19: =IF(COUNTIF(D19:G19, "Must have")>0, "Must have", IF(COUNTIF(D19:G19, "Should have")>0, "Should have", IF(COUNTIF(D19:G19, "Could have")>0, "Could have", IF(COUNTIF(D19:G19, "Won’t have")>0, "Won’t have", "-")))) -> - | I19: =IF(OR(ISNUMBER(SEARCH("Must have",H19)),ISNUMBER(SEARCH("Should have",H19))),B19,"")
A20: 14 | B20: Dependability | C20: A user's trust in the app's ability to perform consistently, predictably, and securely, meeting their expectations for control and safety during interaction. | H20: =IF(COUNTIF(D20:G20, "Must have")>0, "Must have", IF(COUNTIF(D20:G20, "Should have")>0, "Should have", IF(COUNTIF(D20:G20, "Could have")>0, "Could have", IF(COUNTIF(D20:G20, "Won’t have")>0, "Won’t have", "-")))) -> - | I20: =IF(OR(ISNUMBER(SEARCH("Must have",H20)),ISNUMBER(SEARCH("Should have",H20))),B20,"")
A21: 15 | B21: External Constraints | C21: External constraints represent limitations that exist outside the product or service itself and can indirectly impact the user experience (UX). These constraints are often technical in nature and encompass factors that the product must accommodate to ensure optimal performance and usability. | H21: =IF(COUNTIF(D21:G21, "Must have")>0, "Must have", IF(COUNTIF(D21:G21, "Should have")>0, "Should have", IF(COUNTIF(D21:G21, "Could have")>0, "Could have", IF(COUNTIF(D21:G21, "Won’t have")>0, "Won’t have", "-")))) -> - | I21: =IF(OR(ISNUMBER(SEARCH("Must have",H21)),ISNUMBER(SEARCH("Should have",H21))),B21,"")
A22: 16 | B22: Independability | C22: The degree to which a mobile app allows users to achieve their goals and complete tasks within the app itself, with minimal reliance on external factors or assistance. | H22: =IF(COUNTIF(D22:G22, "Must have")>0, "Must have", IF(COUNTIF(D22:G22, "Should have")>0, "Should have", IF(COUNTIF(D22:G22, "Could have")>0, "Could have", IF(COUNTIF(D22:G22, "Won’t have")>0, "Won’t have", "-")))) -> - | I22: =IF(OR(ISNUMBER(SEARCH("Must have",H22)),ISNUMBER(SEARCH("Should have",H22))),B22,"")
A23: 17 | B23: Updateness | C23: It refers to the frequency and timeliness of updates released for a mobile app. It includes the regularity of bug fixes, feature enhancements, security patches, and compatibility updates. | H23: =IF(COUNTIF(D23:G23, "Must have")>0, "Must have", IF(COUNTIF(D23:G23, "Should have")>0, "Should have", IF(COUNTIF(D23:G23, "Could have")>0, "Could have", IF(COUNTIF(D23:G23, "Won’t have")>0, "Won’t have", "-")))) -> - | I23: =IF(OR(ISNUMBER(SEARCH("Must have",H23)),ISNUMBER(SEARCH("Should have",H23))),B23,"")
A24: 18 | B24: Accessibility | C24: Accessibility refers to the design of mobile apps such that they can be easily used and understood by people of all abilities. | H24: =IF(COUNTIF(D24:G24, "Must have")>0, "Must have", IF(COUNTIF(D24:G24, "Should have")>0, "Should have", IF(COUNTIF(D24:G24, "Could have")>0, "Could have", IF(COUNTIF(D24:G24, "Won’t have")>0, "Won’t have", "-")))) -> - | I24: =IF(OR(ISNUMBER(SEARCH("Must have",H24)),ISNUMBER(SEARCH("Should have",H24))),B24,"")
A25: 19 | B25: Trustworthiness | C25: Trustworthiness in mobile UX reflects the user's confidence in an app's reliability, security, and the organization behind it. | H25: =IF(COUNTIF(D25:G25, "Must have")>0, "Must have", IF(COUNTIF(D25:G25, "Should have")>0, "Should have", IF(COUNTIF(D25:G25, "Could have")>0, "Could have", IF(COUNTIF(D25:G25, "Won’t have")>0, "Won’t have", "-")))) -> - | I25: =IF(OR(ISNUMBER(SEARCH("Must have",H25)),ISNUMBER(SEARCH("Should have",H25))),B25,"")
A26: 20 | B26: Information Quality | C26: Refers to the accuracy, meaningfulness, and comprehensiveness/Completeness of the information presented within the app or service. | H26: =IF(COUNTIF(D26:G26, "Must have")>0, "Must have", IF(COUNTIF(D26:G26, "Should have")>0, "Should have", IF(COUNTIF(D26:G26, "Could have")>0, "Could have", IF(COUNTIF(D26:G26, "Won’t have")>0, "Won’t have", "-")))) -> - | I26: =IF(OR(ISNUMBER(SEARCH("Must have",H26)),ISNUMBER(SEARCH("Should have",H26))),B26,"")
... A30: 24 | B30: Automation & AI | C30: Refer to leveraging machine learning, artificial intelligence, and automated processes to enhance UX, streamline interactions, and provide efficient and intelligent application features, for instance, automating tasks, predictive analytics, and smart notifications, and offering intelligent assistance to users through intelligent search, chatbots, and recommendation systems. | H30: =IF(COUNTIF(D30:G30, "Must have")>0, "Must have", IF(COUNTIF(D30:G30, "Should have")>0, "Should have", IF(COUNTIF(D30:G30, "Could have")>0, "Could have", IF(COUNTIF(D30:G30, "Won’t have")>0, "Won’t have", "-")))) -> - | I30: =IF(OR(ISNUMBER(SEARCH("Must have",H30)),ISNUMBER(SEARCH("Should have",H30))),B30,"")
A31: Context Dimension
A32: 25 | B32: User Inclusivity | C32: User Inclusivity is the philosophy of designing experiences that cater to a diverse range of users. It delves into understanding users' unique characteristics, preferences, and backgrounds, guiding the creation of tailored app experiences that resonate with each individual. This encompasses demographics, knowledge, needs, cultural background, and personal values. | H32: =IF(COUNTIF(D32:G32, "Must have")>0, "Must have", IF(COUNTIF(D32:G32, "Should have")>0, "Should have", IF(COUNTIF(D32:G32, "Could have")>0, "Could have", IF(COUNTIF(D32:G32, "Won’t have")>0, "Won’t have", "-")))) -> - | I32: =IF(OR(ISNUMBER(SEARCH("Must have",H32)),ISNUMBER(SEARCH("Should have",H32))),B32,"")
A33: 26 | B33: Quality Of Interaction | C33: The quality of interaction in a mobile app's UX refers to how smoothly and effectively users can communicate with and achieve their goals within the app. | H33: =IF(COUNTIF(D33:G33, "Must have")>0, "Must have", IF(COUNTIF(D33:G33, "Should have")>0, "Should have", IF(COUNTIF(D33:G33, "Could have")>0, "Could have", IF(COUNTIF(D33:G33, "Won’t have")>0, "Won’t have", "-")))) -> - | I33: =IF(OR(ISNUMBER(SEARCH("Must have",H33)),ISNUMBER(SEARCH("Should have",H33))),B33,"")
A34: 27 | B34: Context Of Use | C34: Refers to the comprehensive understanding and consideration of the circumstances, environment, and user conditions in which individuals interact with mobile devices and applications. | H34: =IF(COUNTIF(D34:G34, "Must have")>0, "Must have", IF(COUNTIF(D34:G34, "Should have")>0, "Should have", IF(COUNTIF(D34:G34, "Could have")>0, "Could have", IF(COUNTIF(D34:G34, "Won’t have")>0, "Won’t have", "-")))) -> - | I34: =IF(OR(ISNUMBER(SEARCH("Must have",H34)),ISNUMBER(SEARCH("Should have",H34))),B34,"")

Sheet AHP(Structure the hierarchy)
A1: Stage-2: After completing the MoSCoW method, use the Analytic Hierarchy Process (AHP) to rank the prioritized UX aspects (from Step 1) according to the four criteria below. Please proceed to the sheets labeled "Compare and weight the criteria," "User profiles," "App domain specificity," "Task Complexity," and "Feasibility." Follow the instructions in each sheet to automatically generate the ranked list on the final sheet labeled "Total scores."
A2: Structure the hierarchy
A3: Goal: | B3: Rank the prioritized UX aspect(alternatives).
A4: Criteria: | B4: User profiles | C4: App domain specificity | D4: Task Complexity | E4: Feasibility
A5: Alternatives (UX Aspects):
B6: {=_xlfn._xlws.FILTER('MoSCoW Method'!I6:I34, 'MoSCoW Method'!I6:I34<>"")} -> #VALUE!

Sheet Compare and weight the criteria
A1: Assess Relative Importance: Use the nine-point scale provided on the side to compare the relative importance of each criterion in the row to each criterion in the column (orange cells). Example Comparison: Ask yourself, "How much more important is the criterion 'User profiles' (in the row) than 'App domain specificity' (in the column)?" and assign a number from the scale. Continue by comparing "User profiles" (in the row) to "Task Complexity" (in the column), and then to "Feasibility" (in the column), and so on, until all criteria in the rows have been pairwise compared to the ones in the columns. Please Note (Less Important Criterion): If you believe a criterion in the row is less important than one in the column, use the reciprocals of the nine-point scale, where 1 ("equally unimportant") to 1/9 ("extreme unimportance"). For example, if "User profiles" (in the row) is less important than "App domain specificity" (in the column), you might assign a value like =1/3. For more info please visit: | I1: Scale: 1: Equally important 2: Equally to moderately more important 3: Moderately more important 4: Moderately to strongly more important 5: Strongly more important 6: Strongly to very strongly more important 7: Very strongly more important 8: Very strongly to extremely more important 9: Extremely more important
A2: For more info, please visit: https://www.1000minds.com/decision-making/analytic-hierarchy-process-ahp
B4: Pairwise comparison matrix
B5: User profiles | C5: App domain specificity | D5: Task Complexity | E5: Feasibility
A6: User profiles | B6: 1
A7: App domain specificity | B7: =IF(C6=0,0,1/C6) -> 0 | C7: 1
A8: Task Complexity | B8: =IF(D6=0,0,1/D6) -> 0 | C8: =IF(D7=0,0,1/D7) -> 0 | D8: 1
A9: Feasibility | B9: =IF(E6=0,0,1/E6) -> 0 | C9: =IF(E7=0,0,1/E7) -> 0 | D9: =IF(E8=0,0,1/E8) -> 0 | E9: 1
B11: Calculate criterion weights | J11: Square the matrix
B12: User profiles | C12: App domain specificity | D12: Task Complexity | E12: Feasibility | F12: Row total | G12: Weight | J12: User profiles | K12: App domain specificity | L12: Task Complexity | M12: Feasibility | N12: Row total | O12: Weight
A13: User profiles | B13: =$B$6*B6+$C$6*B7+$D$6*B8+$E$6*B9 -> 1 | C13: =$B$6*C6+$C$6*C7+$D$6*C8+$E$6*C9 -> 0 | D13: =$B$6*D6+$C$6*D7+$D$6*D8+$E$6*D9 -> 0 | E13: =$B$6*E6+$C$6*E7+$D$6*E8+$E$6*E9 -> 0 | F13: =SUM(B13:E13) -> 1 | G13: =F13/$F$17 -> 0.25 | I13: User profiles | J13: =$B$13*B13+$C$13*B14+$D$13*B15+$E$13*B16 -> 1 | K13: =$B$13*C13+$C$13*C14+$D$13*C15+$E$13*C16 -> 0 | L13: =$B$13*D13+$C$13*D14+$D$13*D15+$E$13*D16 -> 0 | M13: =$B$13*E13+$C$13*E14+$D$13*E15+$E$13*E16 -> 0 | N13: =SUM(J13:M13) -> 1 | O13: =N13/$N$17 -> 0.25
A14: App domain specificity | B14: =$B$7*B6+$C$7*B7+$D$7*B8+$E$7*B9 -> 0 | C14: =$B$7*C6+$C$7*C7+$D$7*C8+$E$7*C9 -> 1 | D14: =$B$7*D6+$C$7*D7+$D$7*D8+$E$7*D9 -> 0 | E14: =$B$7*E6+$C$7*E7+$D$7*E8+$E$7*E9 -> 0 | F14: =SUM(B14:E14) -> 1 | G14: =F14/$F$17 -> 0.25 | I14: App domain specificity | J14: =$B$14*B13+$C$14*B14+$D$14*B15+$E$14*B16 -> 0 | K14: =$B$14*C13+$C$14*C14+$D$14*C15+$E$14*C16 -> 1 | L14: =$B$14*D13+$C$14*D14+$D$14*D15+$E$14*D16 -> 0 | M14: =$B$14*E13+$C$14*E14+$D$14*E15+$E$14*E16 -> 0 | N14: =SUM(J14:M14) -> 1 | O14: =N14/$N$17 -> 0.25
A15: Task Complexity | B15: =$B$8*B6+$C$8*B7+$D$8*B8+$E$8*B9 -> 0 | C15: =$B$8*C6+$C$8*C7+$D$8*C8+$E$8*C9 -> 0 | D15: =$B$8*D6+$C$8*D7+$D$8*D8+$E$8*D9 -> 1 | E15: =$B$8*E6+$C$8*E7+$D$8*E8+$E$8*E9 -> 0 | F15: =SUM(B15:E15) -> 1 | G15: =F15/$F$17 -> 0.25 | I15: Task Complexity | J15: =$B$15*B13+$C$15*B14+$D$15*B15+$E$15*B16 -> 0 | K15: =$B$15*C13+$C$15*C14+$D$15*C15+$E$15*C16 -> 0 | L15: =$B$15*D13+$C$15*D14+$D$15*D15+$E$15*D16 -> 1 | M15: =$B$15*E13+$C$15*E14+$D$15*E15+$E$15*E16 -> 0 | N15: =SUM(J15:M15) -> 1 | O15: =N15/$N$17 -> 0.25
A16: Feasibility | B16: =$B$9*B6+$C$9*B7+$D$9*B8+$E$9*B9 -> 0 | C16: =$B$9*C6+$C$9*C7+$D$9*C8+$E$9*C9 -> 0 | D16: =$B$9*D6+$C$9*D7+$D$9*D8+$E$9*D9 -> 0 | E16: =$B$9*E6+$C$9*E7+$D$9*E8+$E$9*E9 -> 1 | F16: =SUM(B16:E16) -> 1 | G16: =F16/$F$17 -> 0.25 | I16: Feasibility | J16: =$B$16*B13+$C$16*B14+$D$16*B15+$E$16*B16 -> 0 | K16: =$B$16*C13+$C$16*C14+$D$16*C15+$E$16*C16 -> 0 | L16: =$B$16*D13+$C$16*D14+$D$16*D15+$E$16*D16 -> 0 | M16: =$B$16*E13+$C$16*E14+$D$16*E15+$E$16*E16 -> 1 | N16: =SUM(J16:M16) -> 1 | O16: =N16/$N$17 -> 0.25
E17: Sum: | F17: =SUM(F13:F16) -> 4 | G17: =SUM(G13:G16) -> 1 | M17: Sum: | N17: =SUM(N13:N16) -> 4 | O17: =SUM(O13:O16) -> 1

Sheet User Profiles
A1: Evaluate alternatives: Use the same nine-point scale provided beside to compare the relative importance of each alternative (prioritized aspect) in the row to each alternative in the column (orange cells) concerning the "User profiles" criterion. Please only input a number in the cells with the column header if the header (-) keeps empty. Example Comparison: Ask yourself, "With respect to the criterion "User profiles," how much more do you prefer alternative (i.e., X "in the row" to alternative Y" in the column"? And assign a number from the scale. Continue by comparing each alternative (in the row) to all alternatives (in the columns) one by one concerning the "User profile" criterion until all alternatives in the rows have been pairwise compared to the ones in the columns. Please Note (Less Important alternative): If you believe an alternative in the row is less important than one in the column, use the reciprocals of the nine-point scale, where 1 ("equally unimportant") to 1/9 ("extreme unimportance"). For example, if alternative X (in the row) is less important than alternative Y (in the column), you might assign a value like =1/3. | M1: Scale: 1: Equally important 2: Equally to moderately more important 3: Moderately more important 4: Moderately to strongly more important 5: Strongly more important 6: Strongly to very strongly more important 7: Very strongly more important 8: Very strongly to extremely more important 9: Extremely more important
A2: For more info, please visit: https://www.1000minds.com/decision-making/analytic-hierarchy-process-ahp
G4: User profiles(alternatives pairwise comparison matrix)
B5: {=IF(TRANSPOSE(A6:A32)=0,"-",TRANSPOSE(A6:A32))} -> #VALUE! | C5: - | D5: - | E5: - | F5: - | G5: - | H5: - | I5: - | J5: - | K5: - | L5: - | M5: - | N5: - | O5: - | P5: - | Q5: - | R5: - | S5: - | T5: - | U5: - | V5: - | W5: - | X5: - | Y5: - | Z5: - | AA5: - | AB5: -
A6: {=_xlfn._xlws.FILTER('AHP(Structure the hierarchy)'!B6:B33, 'AHP(Structure the hierarchy)'!B6:B33<>"")} -> #VALUE! | B6: 1
B7: =IF(C6=0,0,1/C6) -> 0 | C7: 1
B8: =IF(D6=0,0,1/D6) -> 0 | C8: =IF(D7=0,0,1/D7) -> 0 | D8: 1
B9: =IF(E6=0,0,1/E6) -> 0 | C9: =IF(E7=0,0,1/E7) -> 0 | D9: =IF(E8=0,0,1/E8) -> 0 | E9: 1
B10: =IF(F6=0,0,1/F6) -> 0 | C10: =IF(F7=0,0,1/F7) -> 0 | D10: =IF(F8=0,0,1/F8) -> 0 | E10: =IF(F9=0,0,1/F9) -> 0 | F10: 1
B11: =IF(G6=0,0,1/G6) -> 0 | C11: =IF(G7=0,0,1/G7) -> 0 | D11: =IF(G8=0,0,1/G8) -> 0 | E11: =IF(G9=0,0,1/G9) -> 0 | F11: =IF(G10=0,0,1/G10) -> 0 | G11: 1
B12: =IF(H6=0,0,1/H6) -> 0 | C12: =IF(H7=0,0,1/H7) -> 0 | D12: =IF(H8=0,0,1/H8) -> 0 | E12: =IF(H9=0,0,1/H9) -> 0 | F12: =IF(H10=0,0,1/H10) -> 0 | G12: =IF(H11=0,0,1/H11) -> 0 | H12: 1
B13: =IF(I6=0,0,1/I6) -> 0 | C13: =IF(I7=0,0,1/I7) -> 0 | D13: =IF(I8=0,0,1/I8) -> 0 | E13: =IF(I9=0,0,1/I9) -> 0 | F13: =IF(I10=0,0,1/I10) -> 0 | G13: =IF(I11=0,0,1/I11) -> 0 | H13: =IF(I12=0,0,1/I12) -> 0 | I13: 1
B14: =IF(J6=0,0,1/J6) -> 0 | C14: =IF(J7=0,0,1/J7) -> 0 | D14: =IF(J8=0,0,1/J8) -> 0 | E14: =IF(J9=0,0,1/J9) -> 0 | F14: =IF(J10=0,0,1/J10) -> 0 | G14: =IF(J11=0,0,1/J11) -> 0 | H14: =IF(J12=0,0,1/J12) -> 0 | I14: =IF(J13=0,0,1/J13) -> 0 | J14: 1
B15: =IF(K6=0,0,1/K6) -> 0 | C15: =IF(K7=0,0,1/K7) -> 0 | D15: =IF(K8=0,0,1/K8) -> 0 | E15: =IF(K9=0,0,1/K9) -> 0 | F15: =IF(K10=0,0,1/K10) -> 0 | G15: =IF(K11=0,0,1/K11) -> 0 | H15: =IF(K12=0,0,1/K12) -> 0 | I15: =IF(K13=0,0,1/K13) -> 0 | J15: =IF(K14=0,0,1/K14) -> 0 | K15: 1
B16: =IF(L6=0,0,1/L6) -> 0 | C16: =IF(L7=0,0,1/L7) -> 0 | D16: =IF(L8=0,0,1/L8) -> 0 | E16: =IF(L9=0,0,1/L9) -> 0 | F16: =IF(L10=0,0,1/L10) -> 0 | G16: =IF(L11=0,0,1/L11) -> 0 | H16: =IF(L12=0,0,1/L12) -> 0 | I16: =IF(L13=0,0,1/L13) -> 0 | J16: =IF(L14=0,0,1/L14) -> 0 | K16: =IF(L15=0,0,1/L15) -> 0 | L16: 1
B17: =IF(M6=0,0,1/M6) -> 0 | C17: =IF(M7=0,0,1/M7) -> 0 | D17: =IF(M8=0,0,1/M8) -> 0 | E17: =IF(M9=0,0,1/M9) -> 0 | F17: =IF(M10=0,0,1/M10) -> 0 | G17: =IF(M11=0,0,1/M11) -> 0 | H17: =IF(M12=0,0,1/M12) -> 0 | I17: =IF(M13=0,0,1/M13) -> 0 | J17: =IF(M14=0,0,1/M14) -> 0 | K17: =IF(M15=0,0,1/M15) -> 0 | L17: =IF(M16=0,0,1/M16) -> 0 | M17: 1
B18: =IF(N6=0,0,1/N6) -> 0 | C18: =IF(N7=0,0,1/N7) -> 0 | D18: =IF(N8=0,0,1/N8) -> 0 | E18: =IF(N9=0,0,1/N9) -> 0 | F18: =IF(N10=0,0,1/N10) -> 0 | G18: =IF(N11=0,0,1/N11) -> 0 | H18: =IF(N12=0,0,1/N12) -> 0 | I18: =IF(N13=0,0,1/N13) -> 0 | J18: =IF(N14=0,0,1/N14) -> 0 | K18: =IF(N15=0,0,1/N15) -> 0 | L18: =IF(N16=0,0,1/N16) -> 0 | M18: =IF(N17=0,0,1/N17) -> 0 | N18: 1
B19: =IF(O6=0,0,1/O6) -> 0 | C19: =IF(O7=0,0,1/O7) -> 0 | D19: =IF(O8=0,0,1/O8) -> 0 | E19: =IF(O9=0,0,1/O9) -> 0 | F19: =IF(O10=0,0,1/O10) -> 0 | G19: =IF(O11=0,0,1/O11) -> 0 | H19: =IF(O12=0,0,1/O12) -> 0 | I19: =IF(O13=0,0,1/O13) -> 0 | J19: =IF(O14=0,0,1/O14) -> 0 | K19: =IF(O15=0,0,1/O15) -> 0 | L19: =IF(O16=0,0,1/O16) -> 0 | M19: =IF(O17=0,0,1/O17) -> 0 | N19: =IF(O18=0,0,1/O18) -> 0 | O19: 1
B20: =IF(P6=0,0,1/P6) -> 0 | C20: =IF(P7=0,0,1/P7) -> 0 | D20: =IF(P8=0,0,1/P8) -> 0 | E20: =IF(P9=0,0,1/P9) -> 0 | F20: =IF(P10=0,0,1/P10) -> 0 | G20: =IF(P11=0,0,1/P11) -> 0 | H20: =IF(P12=0,0,1/P12) -> 0 | I20: =IF(P13=0,0,1/P13) -> 0 | J20: =IF(P14=0,0,1/P14) -> 0 | K20: =IF(P15=0,0,1/P15) -> 0 | L20: =IF(P16=0,0,1/P16) -> 0 | M20: =IF(P17=0,0,1/P17) -> 0 | N20: =IF(P18=0,0,1/P18) -> 0 | O20: =IF(P19=0,0,1/P19) -> 0 | P20: 1
B21: =IF(Q6=0,0,1/Q6) -> 0 | C21: =IF(Q7=0,0,1/Q7) -> 0 | D21: =IF(Q8=0,0,1/Q8) -> 0 | E21: =IF(Q9=0,0,1/Q9) -> 0 | F21: =IF(Q10=0,0,1/Q10) -> 0 | G21: =IF(Q11=0,0,1/Q11) -> 0 | H21: =IF(Q12=0,0,1/Q12) -> 0 | I21: =IF(Q13=0,0,1/Q13) -> 0 | J21: =IF(Q14=0,0,1/Q14) -> 0 | K21: =IF(Q15=0,0,1/Q15) -> 0 | L21: =IF(Q16=0,0,1/Q16) -> 0 | M21: =IF(Q17=0,0,1/Q17) -> 0 | N21: =IF(Q18=0,0,1/Q18) -> 0 | O21: =IF(Q19=0,0,1/Q19) -> 0 | P21: =IF(Q20=0,0,1/Q20) -> 0 | Q21: 1
B22: =IF(R6=0,0,1/R6) -> 0 | C22: =IF(R7=0,0,1/R7) -> 0 | D22: =IF(R8=0,0,1/R8) -> 0 | E22: =IF(R9=0,0,1/R9) -> 0 | F22: =IF(R10=0,0,1/R10) -> 0 | G22: =IF(R11=0,0,1/R11) -> 0 | H22: =IF(R12=0,0,1/R12) -> 0 | I22: =IF(R13=0,0,1/R13) -> 0 | J22: =IF(R14=0,0,1/R14) -> 0 | K22: =IF(R15=0,0,1/R15) -> 0 | L22: =IF(R16=0,0,1/R16) -> 0 | M22: =IF(R17=0,0,1/R17) -> 0 | N22: =IF(R18=0,0,1/R18) -> 0 | O22: =IF(R19=0,0,1/R19) -> 0 | P22: =IF(R20=0,0,1/R20) -> 0 | Q22: =IF(R21=0,0,1/R21) -> 0 | R22: 1
B23: =IF(S6=0,0,1/S6) -> 0 | C23: =IF(S7=0,0,1/S7) -> 0 | D23: =IF(S8=0,0,1/S8) -> 0 | E23: =IF(S9=0,0,1/S9) -> 0 | F23: =IF(S10=0,0,1/S10) -> 0 | G23: =IF(S11=0,0,1/S11) -> 0 | H23: =IF(S12=0,0,1/S12) -> 0 | I23: =IF(S13=0,0,1/S13) -> 0 | J23: =IF(S14=0,0,1/S14) -> 0 | K23: =IF(S15=0,0,1/S15) -> 0 | L23: =IF(S16=0,0,1/S16) -> 0 | M23: =IF(S17=0,0,1/S17) -> 0 | N23: =IF(S18=0,0,1/S18) -> 0 | O23: =IF(S19=0,0,1/S19) -> 0 | P23: =IF(S20=0,0,1/S20) -> 0 | Q23: =IF(S21=0,0,1/S21) -> 0 | R23: =IF(S22=0,0,1/S22) -> 0 | S23: 1
B24: =IF(T6=0,0,1/T6) -> 0 | C24: =IF(T7=0,0,1/T7) -> 0 | D24: =IF(T8=0,0,1/T8) -> 0 | E24: =IF(T9=0,0,1/T9) -> 0 | F24: =IF(T10=0,0,1/T10) -> 0 | G24: =IF(T11=0,0,1/T11) -> 0 | H24: =IF(T12=0,0,1/T12) -> 0 | I24: =IF(T13=0,0,1/T13) -> 0 | J24: =IF(T14=0,0,1/T14) -> 0 | K24: =IF(T15=0,0,1/T15) -> 0 | L24: =IF(T16=0,0,1/T16) -> 0 | M24: =IF(T17=0,0,1/T17) -> 0 | N24: =IF(T18=0,0,1/T18) -> 0 | O24: =IF(T19=0,0,1/T19) -> 0 | P24: =IF(T20=0,0,1/T20) -> 0 | Q24: =IF(T21=0,0,1/T21) -> 0 | R24: =IF(T22=0,0,1/T22) -> 0 | S24: =IF(T23=0,0,1/T23) -> 0 | T24: 1
B25: =IF(U6=0,0,1/U6) -> 0 | C25: =IF(U7=0,0,1/U7) -> 0 | D25: =IF(U8=0,0,1/U8) -> 0 | E25: =IF(U9=0,0,1/U9) -> 0 | F25: =IF(U10=0,0,1/U10) -> 0 | G25: =IF(U11=0,0,1/U11) -> 0 | H25: =IF(U12=0,0,1/U12) -> 0 | I25: =IF(U13=0,0,1/U13) -> 0 | J25: =IF(U14=0,0,1/U14) -> 0 | K25: =IF(U15=0,0,1/U15) -> 0 | L25: =IF(U16=0,0,1/U16) -> 0 | M25: =IF(U17=0,0,1/U17) -> 0 | N25: =IF(U18=0,0,1/U18) -> 0 | O25: =IF(U19=0,0,1/U19) -> 0 | P25: =IF(U20=0,0,1/U20) -> 0 | Q25: =IF(U21=0,0,1/U21) -> 0 | R25: =IF(U22=0,0,1/U22) -> 0 | S25: =IF(U23=0,0,1/U23) -> 0 | T25: =IF(U24=0,0,1/U24) -> 0 | U25: 1
B26: =IF(V6=0,0,1/V6) -> 0 | C26: =IF(V7=0,0,1/V7) -> 0 | D26: =IF(V8=0,0,1/V8) -> 0 | E26: =IF(V9=0,0,1/V9) -> 0 | F26: =IF(V10=0,0,1/V10) -> 0 | G26: =IF(V11=0,0,1/V11) -> 0 | H26: =IF(V12=0,0,1/V12) -> 0 | I26: =IF(V13=0,0,1/V13) -> 0 | J26: =IF(V14=0,0,1/V14) -> 0 | K26: =IF(V15=0,0,1/V15) -> 0 | L26: =IF(V16=0,0,1/V16) -> 0 | M26: =IF(V17=0,0,1/V17) -> 0 | N26: =IF(V18=0,0,1/V18) -> 0 | O26: =IF(V19=0,0,1/V19) -> 0 | P26: =IF(V20=0,0,1/V20) -> 0 | Q26: =IF(V21=0,0,1/V21) -> 0 | R26: =IF(V22=0,0,1/V22) -> 0 | S26: =IF(V23=0,0,1/V23) -> 0 | T26: =IF(V24=0,0,1/V24) -> 0 | U26: =IF(V25=0,0,1/V25) -> 0 | V26: 1
B27: =IF(W6=0,0,1/W6) -> 0 | C27: =IF(W7=0,0,1/W7) -> 0 | D27: =IF(W8=0,0,1/W8) -> 0 | E27: =IF(W9=0,0,1/W9) -> 0 | F27: =IF(W10=0,0,1/W10) -> 0 | G27: =IF(W11=0,0,1/W11) -> 0 | H27: =IF(W12=0,0,1/W12) -> 0 | I27: =IF(W13=0,0,1/W13) -> 0 | J27: =IF(W14=0,0,1/W14) -> 0 | K27: =IF(W15=0,0,1/W15) -> 0 | L27: =IF(W16=0,0,1/W16) -> 0 | M27: =IF(W17=0,0,1/W17) -> 0 | N27: =IF(W18=0,0,1/W18) -> 0 | O27: =IF(W19=0,0,1/W19) -> 0 | P27: =IF(W20=0,0,1/W20) -> 0 | Q27: =IF(W21=0,0,1/W21) -> 0 | R27: =IF(W22=0,0,1/W22) -> 0 | S27: =IF(W23=0,0,1/W23) -> 0 | T27: =IF(W24=0,0,1/W24) -> 0 | U27: =IF(W25=0,0,1/W25) -> 0 | V27: =IF(W26=0,0,1/W26) -> 0 | W27: 1
B28: =IF(X6=0,0,1/X6) -> 0 | C28: =IF(X7=0,0,1/X7) -> 0 | D28: =IF(X8=0,0,1/X8) -> 0 | E28: =IF(X9=0,0,1/X9) -> 0 | F28: =IF(X10=0,0,1/X10) -> 0 | G28: =IF(X11=0,0,1/X11) -> 0 | H28: =IF(X12=0,0,1/X12) -> 0 | I28: =IF(X13=0,0,1/X13) -> 0 | J28: =IF(X14=0,0,1/X14) -> 0 | K28: =IF(X15=0,0,1/X15) -> 0 | L28: =IF(X16=0,0,1/X16) -> 0 | M28: =IF(X17=0,0,1/X17) -> 0 | N28: =IF(X18=0,0,1/X18) -> 0 | O28: =IF(X19=0,0,1/X19) -> 0 | P28: =IF(X20=0,0,1/X20) -> 0 | Q28: =IF(X21=0,0,1/X21) -> 0 | R28: =IF(X22=0,0,1/X22) -> 0 | S28: =IF(X23=0,0,1/X23) -> 0 | T28: =IF(X24=0,0,1/X24) -> 0 | U28: =IF(X25=0,0,1/X25) -> 0 | V28: =IF(X26=0,0,1/X26) -> 0 | W28: =IF(X27=0,0,1/X27) -> 0 | X28: 1
B29: =IF(Y6=0,0,1/Y6) -> 0 | C29: =IF(Y7=0,0,1/Y7) -> 0 | D29: =IF(Y8=0,0,1/Y8) -> 0 | E29: =IF(Y9=0,0,1/Y9) -> 0 | F29: =IF(Y10=0,0,1/Y10) -> 0 | G29: =IF(Y11=0,0,1/Y11) -> 0 | H29: =IF(Y12=0,0,1/Y12) -> 0 | I29: =IF(Y13=0,0,1/Y13) -> 0 | J29: =IF(Y14=0,0,1/Y14) -> 0 | K29: =IF(Y15=0,0,1/Y15) -> 0 | L29: =IF(Y16=0,0,1/Y16) -> 0 | M29: =IF(Y17=0,0,1/Y17) -> 0 | N29: =IF(Y18=0,0,1/Y18) -> 0 | O29: =IF(Y19=0,0,1/Y19) -> 0 | P29: =IF(Y20=0,0,1/Y20) -> 0 | Q29: =IF(Y21=0,0,1/Y21) -> 0 | R29: =IF(Y22=0,0,1/Y22) -> 0 | S29: =IF(Y23=0,0,1/Y23) -> 0 | T29: =IF(Y24=0,0,1/Y24) -> 0 | U29: =IF(Y25=0,0,1/Y25) -> 0 | V29: =IF(Y26=0,0,1/Y26) -> 0 | W29: =IF(Y27=0,0,1/Y27) -> 0 | X29: =IF(Y28=0,0,1/Y28) -> 0 | Y29: 1
B30: =IF(Z6=0,0,1/Z6) -> 0 | C30: =IF(Z7=0,0,1/Z7) -> 0 | D30: =IF(Z8=0,0,1/Z8) -> 0 | E30: =IF(Z9=0,0,1/Z9) -> 0 | F30: =IF(Z10=0,0,1/Z10) -> 0 | G30: =IF(Z11=0,0,1/Z11) -> 0 | H30: =IF(Z12=0,0,1/Z12) -> 0 | I30: =IF(Z13=0,0,1/Z13) -> 0 | J30: =IF(Z14=0,0,1/Z14) -> 0 | K30: =IF(Z15=0,0,1/Z15) -> 0 | L30: =IF(Z16=0,0,1/Z16) -> 0 | M30: =IF(Z17=0,0,1/Z17) -> 0 | N30: =IF(Z18=0,0,1/Z18) -> 0 | O30: =IF(Z19=0,0,1/Z19) -> 0 | P30: =IF(Z20=0,0,1/Z20) -> 0 | Q30: =IF(Z21=0,0,1/Z21) -> 0 | R30: =IF(Z22=0,0,1/Z22) -> 0 | S30: =IF(Z23=0,0,1/Z23) -> 0 | T30: =IF(Z24=0,0,1/Z24) -> 0 | U30: =IF(Z25=0,0,1/Z25) -> 0 | V30: =IF(Z26=0,0,1/Z26) -> 0 | W30: =IF(Z27=0,0,1/Z27) -> 0 | X30: =IF(Z28=0,0,1/Z28) -> 0 | Y30: =IF(Z29=0,0,1/Z29) -> 0 | Z30: 1
B31: =IF(AA6=0,0,1/AA6) -> 0 | C31: =IF(AA7=0,0,1/AA7) -> 0 | D31: =IF(AA8=0,0,1/AA8) -> 0 | E31: =IF(AA9=0,0,1/AA9) -> 0 | F31: =IF(AA10=0,0,1/AA10) -> 0 | G31: =IF(AA11=0,0,1/AA11) -> 0 | H31: =IF(AA12=0,0,1/AA12) -> 0 | I31: =IF(AA13=0,0,1/AA13) -> 0 | J31: =IF(AA14=0,0,1/AA14) -> 0 | K31: =IF(AA15=0,0,1/AA15) -> 0 | L31: =IF(AA16=0,0,1/AA16) -> 0 | M31: =IF(AA17=0,0,1/AA17) -> 0 | N31: =IF(AA18=0,0,1/AA18) -> 0 | O31: =IF(AA19=0,0,1/AA19) -> 0 | P31: =IF(AA20=0,0,1/AA20) -> 0 | Q31: =IF(AA21=0,0,1/AA21) -> 0 | R31: =IF(AA22=0,0,1/AA22) -> 0 | S31: =IF(AA23=0,0,1/AA23) -> 0 | T31: =IF(AA24=0,0,1/AA24) -> 0 | U31: =IF(AA25=0,0,1/AA25) -> 0 | V31: =IF(AA26=0,0,1/AA26) -> 0 | W31: =IF(AA27=0,0,1/AA27) -> 0 | X31: =IF(AA28=0,0,1/AA28) -> 0 | Y31: =IF(AA29=0,0,1/AA29) -> 0 | Z31: =IF(AA30=0,0,1/AA30) -> 0 | AA31: 1
B32: =IF(AB6=0,0,1/AB6) -> 0 | C32: =IF(AB7=0,0,1/AB7) -> 0 | D32: =IF(AB8=0,0,1/AB8) -> 0 | E32: =IF(AB9=0,0,1/AB9) -> 0 | F32: =IF(AB10=0,0,1/AB10) -> 0 | G32: =IF(AB11=0,0,1/AB11) -> 0 | H32: =IF(AB12=0,0,1/AB12) -> 0 | I32: =IF(AB13=0,0,1/AB13) -> 0 | J32: =IF(AB14=0,0,1/AB14) -> 0 | K32: =IF(AB15=0,0,1/AB15) -> 0 | L32: =IF(AB16=0,0,1/AB16) -> 0 | M32: =IF(AB17=0,0,1/AB17) -> 0 | N32: =IF(AB18=0,0,1/AB18) -> 0 | O32: =IF(AB19=0,0,1/AB19) -> 0 | P32: =IF(AB20=0,0,1/AB20) -> 0 | Q32: =IF(AB21=0,0,1/AB21) -> 0 | R32: =IF(AB22=0,0,1/AB22) -> 0 | S32: =IF(AB23=0,0,1/AB23) -> 0 | T32: =IF(AB24=0,0,1/AB24) -> 0 | U32: =IF(AB25=0,0,1/AB25) -> 0 | V32: =IF(AB26=0,0,1/AB26) -> 0 | W32: =IF(AB27=0,0,1/AB27) -> 0 | X32: =IF(AB28=0,0,1/AB28) -> 0 | Y32: =IF(AB29=0,0,1/AB29) -> 0 | Z32: =IF(AB30=0,0,1/AB30) -> 0 | AA32: =IF(AB31=0,0,1/AB31) -> 0 | AB32: 1
H34: Calculate alternatives weights
B35: {=IF(TRANSPOSE(A6:A32)=0,"-",TRANSPOSE(A6:A32))} -> #VALUE! | C35: - | D35: - | E35: - | F35: - | G35: - | H35: - | I35: - | J35: - | K35: - | L35: - | M35: - | N35: - | O35: - | P35: - | Q35: - | R35: - | S35: - | T35: - | U35: - | V35: - | W35: - | X35: - | Y35: - | Z35: - | AA35: - | AB35: - | AC35: Row total | AD35: Score
A36: {=_xlfn._xlws.FILTER('AHP(Structure the hierarchy)'!B6:B33, 'AHP(Structure the hierarchy)'!B6:B33<>"")} -> #VALUE! | B36: =IF($B$6=0,0,$B$6*B6+$C$6*B7+$D$6*B8+$E$6*B9+$F$6*B10+$G$6*B11+H6*B12+I6*B13+J6*B14+K6*B15+L6*B16+M6*B17+N6*B18+O6*B19+P6*B20+Q6*B21+R6*B22+S6*B23+T6*B24+U6*B25+V6*B26+W6*B27+X6*B28+Y6*B29+Z6*B30+AA6*B31+AB6*B32) -> 1 | C36: =IF($B$6=0,0,$B$6*C6+$C$6*C7+$D$6*C8+$E$6*C9+$F$6*C10+$G$6*C11+I6*C12+J6*C13+K6*C14+L6*C15+M6*C16+N6*C17+O6*C18+P6*C19+Q6*C20+R6*C21+S6*C22+T6*C23+U6*C24+V6*C25+W6*C26+X6*C27+Y6*C28+Z6*C29+AA6*C30+AB6*C31+AC6*C32) -> 0 | D36: =IF($B$6=0,0,$B$6*D6+$C$6*D7+$D$6*D8+$E$6*D9+$F$6*D10+$G$6*D11+J6*D12+K6*D13+L6*D14+M6*D15+N6*D16+O6*D17+P6*D18+Q6*D19+R6*D20+S6*D21+T6*D22+U6*D23+V6*D24+W6*D25+X6*D26+Y6*D27+Z6*D28+AA6*D29+AB6*D30+AC6*D31+AD6*D32) -> 0 | E36: =IF($B$6=0,0,$B$6*E6+$C$6*E7+$D$6*E8+$E$6*E9+$F$6*E10+$G$6*E11+K6*E12+L6*E13+M6*E14+N6*E15+O6*E16+P6*E17+Q6*E18+R6*E19+S6*E20+T6*E21+U6*E22+V6*E23+W6*E24+X6*E25+Y6*E26+Z6*E27+AA6*E28+AB6*E29+AC6*E30+AD6*E31+AE6*E32) -> 0 | F36: =IF($B$6=0,0,$B$6*F6+$C$6*F7+$D$6*F8+$E$6*F9+$F$6*F10+$G$6*F11+L6*F12+M6*F13+N6*F14+O6*F15+P6*F16+Q6*F17+R6*F18+S6*F19+T6*F20+U6*F21+V6*F22+W6*F23+X6*F24+Y6*F25+Z6*F26+AA6*F27+AB6*F28+AC6*F29+AD6*F30+AE6*F31+AF6*F32) -> 0 | G36: =IF($B$6=0,0,$B$6*G6+$C$6*G7+$D$6*G8+$E$6*G9+$F$6*G10+$G$6*G11+M6*G12+N6*G13+O6*G14+P6*G15+Q6*G16+R6*G17+S6*G18+T6*G19+U6*G20+V6*G21+W6*G22+X6*G23+Y6*G24+Z6*G25+AA6*G26+AB6*G27+AC6*G28+AD6*G29+AE6*G30+AF6*G31+AG6*G32) -> 0 | H36: =IF($B$6=0,0,$B$6*H6+$C$6*H7+$D$6*H8+$E$6*H9+$F$6*H10+$G$6*H11+N6*H12+O6*H13+P6*H14+Q6*H15+R6*H16+S6*H17+T6*H18+U6*H19+V6*H20+W6*H21+X6*H22+Y6*H23+Z6*H24+AA6*H25+AB6*H26+AC6*H27+AD6*H28+AE6*H29+AF6*H30+AG6*H31+AH6*H32) -> 0 | I36: =IF($B$6=0,0,$B$6*I6+$C$6*I7+$D$6*I8+$E$6*I9+$F$6*I10+$G$6*I11+O6*I12+P6*I13+Q6*I14+R6*I15+S6*I16+T6*I17+U6*I18+V6*I19+W6*I20+X6*I21+Y6*I22+Z6*I23+AA6*I24+AB6*I25+AC6*I26+AD6*I27+AE6*I28+AF6*I29+AG6*I30+AH6*I31+AI6*I32) -> 0 | ... AB36: =IF($B$6=0,0,$B$6*AB6+$C$6*AB7+$D$6*AB8+$E$6*AB9+$F$6*AB10+$G$6*AB11+AH6*AB12+AI6*AB13+AJ6*AB14+AK6*AB15+AL6*AB16+AM6*AB17+AN6*AB18+AO6*AB19+AP6*AB20+AQ6*AB21+AR6*AB22+AS6*AB23+AT6*AB24+AU6*AB25+AV6*AB26+AW6*AB27+AX6*AB28+AY6*AB29+AZ6*AB30+BA6*AB31+BB6*AB32) -> 0 | AC36: =SUM(B36:AB36) -> 1 | AD36: =AC36/$AC$63 -> 1
B37: =IF($B$7=0,0,$B$7*B6+$C$7*B7+$D$7*B8+$E$7*B9+$F$7*B10+$G$7*B11+$H$7*B12+$I$7*B13+$J$7*B14+$K$7*B15+$L$7*B16+$M$7*B17+$N$7*B18+$O$7*B19+$P$7*B20+$Q$7*B21+$R$7*B22+$S$7*B23+$T$7*B24+$U$7*B25+$V$7*B26+$W$7*B27+$X$7*B28+$Y$7*B29+$Z$7*B30+$AA$7*B31+$AB$7*B32) -> 0 | C37: =IF($B$7=0,0,$B$7*C6+$C$7*C7+$D$7*C8+$E$7*C9+$F$7*C10+$G$7*C11+$H$7*C12+$I$7*C13+$J$7*C14+$K$7*C15+$L$7*C16+$M$7*C17+$N$7*C18+$O$7*C19+$P$7*C20+$Q$7*C21+$R$7*C22+$S$7*C23+$T$7*C24+$U$7*C25+$V$7*C26+$W$7*C27+$X$7*C28+$Y$7*C29+$Z$7*C30+$AA$7*C31+$AB$7*C32) -> 0 | D37: =IF($B$7=0,0,$B$7*D6+$C$7*D7+$D$7*D8+$E$7*D9+$F$7*D10+$G$7*D11+$H$7*D12+$I$7*D13+$J$7*D14+$K$7*D15+$L$7*D16+$M$7*D17+$N$7*D18+$O$7*D19+$P$7*D20+$Q$7*D21+$R$7*D22+$S$7*D23+$T$7*D24+$U$7*D25+$V$7*D26+$W$7*D27+$X$7*D28+$Y$7*D29+$Z$7*D30+$AA$7*D31+$AB$7*D32) -> 0 | E37: =IF($B$7=0,0,$B$7*E6+$C$7*E7+$D$7*E8+$E$7*E9+$F$7*E10+$G$7*E11+$H$7*E12+$I$7*E13+$J$7*E14+$K$7*E15+$L$7*E16+$M$7*E17+$N$7*E18+$O$7*E19+$P$7*E20+$Q$7*E21+$R$7*E22+$S$7*E23+$T$7*E24+$U$7*E25+$V$7*E26+$W$7*E27+$X$7*E28+$Y$7*E29+$Z$7*E30+$AA$7*E31+$AB$7*E32) -> 0 | F37: =IF($B$7=0,0,$B$7*F6+$C$7*F7+$D$7*F8+$E$7*F9+$F$7*F10+$G$7*F11+$H$7*F12+$I$7*F13+$J$7*F14+$K$7*F15+$L$7*F16+$M$7*F17+$N$7*F18+$O$7*F19+$P$7*F20+$Q$7*F21+$R$7*F22+$S$7*F23+$T$7*F24+$U$7*F25+$V$7*F26+$W$7*F27+$X$7*F28+$Y$7*F29+$Z$7*F30+$AA$7*F31+$AB$7*F32) -> 0 | G37: =IF($B$7=0,0,$B$7*G6+$C$7*G7+$D$7*G8+$E$7*G9+$F$7*G10+$G$7*G11+$H$7*G12+$I$7*G13+$J$7*G14+$K$7*G15+$L$7*G16+$M$7*G17+$N$7*G18+$O$7*G19+$P$7*G20+$Q$7*G21+$R$7*G22+$S$7*G23+$T$7*G24+$U$7*G25+$V$7*G26+$W$7*G27+$X$7*G28+$Y$7*G29+$Z$7*G30+$AA$7*G31+$AB$7*G32) -> 0 | H37: =IF($B$7=0,0,$B$7*H6+$C$7*H7+$D$7*H8+$E$7*H9+$F$7*H10+$G$7*H11+$H$7*H12+$I$7*H13+$J$7*H14+$K$7*H15+$L$7*H16+$M$7*H17+$N$7*H18+$O$7*H19+$P$7*H20+$Q$7*H21+$R$7*H22+$S$7*H23+$T$7*H24+$U$7*H25+$V$7*H26+$W$7*H27+$X$7*H28+$Y$7*H29+$Z$7*H30+$AA$7*H31+$AB$7*H32) -> 0 | I37: =IF($B$7=0,0,$B$7*I6+$C$7*I7+$D$7*I8+$E$7*I9+$F$7*I10+$G$7*I11+$H$7*I12+$I$7*I13+$J$7*I14+$K$7*I15+$L$7*I16+$M$7*I17+$N$7*I18+$O$7*I19+$P$7*I20+$Q$7*I21+$R$7*I22+$S$7*I23+$T$7*I24+$U$7*I25+$V$7*I26+$W$7*I27+$X$7*I28+$Y$7*I29+$Z$7*I30+$AA$7*I31+$AB$7*I32) -> 0 | ... AB37: =IF($B$7=0,0,$B$7*AB6+$C$7*AB7+$D$7*AB8+$E$7*AB9+$F$7*AB10+$G$7*AB11+$H$7*AB12+$I$7*AB13+$J$7*AB14+$K$7*AB15+$L$7*AB16+$M$7*AB17+$N$7*AB18+$O$7*AB19+$P$7*AB20+$Q$7*AB21+$R$7*AB22+$S$7*AB23+$T$7*AB24+$U$7*AB25+$V$7*AB26+$W$7*AB27+$X$7*AB28+$Y$7*AB29+$Z$7*AB30+$AA$7*AB31+$AB$7*AB32) -> 0 | AC37: =SUM(B37:AB37) -> 0 | AD37: =AC37/$AC$63 -> 0
B38: =IF($B$8=0,0,$B$8*B6+$C$8*B7+$D$8*B8+$E$8*B9+$F$8*B10+$G$8*B11+$H$8*B12+$I$8*B13+$J$8*B14+$K$8*B15+$L$8*B16+$M$8*B17+$N$8*B18+$O$8*B19+$P$8*B20+$Q$8*B21+$R$8*B22+$S$8*B23+$T$8*B24+$U$8*B25+$V$8*B26+$W$8*B27+$X$8*B28+$Y$8*B29+$Z$8*B30+$AA$8*B31+$AB$8*B32) -> 0 | C38: =IF($B$8=0,0,$B$8*C6+$C$8*C7+$D$8*C8+$E$8*C9+$F$8*C10+$G$8*C11+$H$8*C12+$I$8*C13+$J$8*C14+$K$8*C15+$L$8*C16+$M$8*C17+$N$8*C18+$O$8*C19+$P$8*C20+$Q$8*C21+$R$8*C22+$S$8*C23+$T$8*C24+$U$8*C25+$V$8*C26+$W$8*C27+$X$8*C28+$Y$8*C29+$Z$8*C30+$AA$8*C31+$AB$8*C32) -> 0 | D38: =IF($B$8=0,0,$B$8*D6+$C$8*D7+$D$8*D8+$E$8*D9+$F$8*D10+$G$8*D11+$H$8*D12+$I$8*D13+$J$8*D14+$K$8*D15+$L$8*D16+$M$8*D17+$N$8*D18+$O$8*D19+$P$8*D20+$Q$8*D21+$R$8*D22+$S$8*D23+$T$8*D24+$U$8*D25+$V$8*D26+$W$8*D27+$X$8*D28+$Y$8*D29+$Z$8*D30+$AA$8*D31+$AB$8*D32) -> 0 | E38: =IF($B$8=0,0,$B$8*E6+$C$8*E7+$D$8*E8+$E$8*E9+$F$8*E10+$G$8*E11+$H$8*E12+$I$8*E13+$J$8*E14+$K$8*E15+$L$8*E16+$M$8*E17+$N$8*E18+$O$8*E19+$P$8*E20+$Q$8*E21+$R$8*E22+$S$8*E23+$T$8*E24+$U$8*E25+$V$8*E26+$W$8*E27+$X$8*E28+$Y$8*E29+$Z$8*E30+$AA$8*E31+$AB$8*E32) -> 0 | F38: =IF($B$8=0,0,$B$8*F6+$C$8*F7+$D$8*F8+$E$8*F9+$F$8*F10+$G$8*F11+$H$8*F12+$I$8*F13+$J$8*F14+$K$8*F15+$L$8*F16+$M$8*F17+$N$8*F18+$O$8*F19+$P$8*F20+$Q$8*F21+$R$8*F22+$S$8*F23+$T$8*F24+$U$8*F25+$V$8*F26+$W$8*F27+$X$8*F28+$Y$8*F29+$Z$8*F30+$AA$8*F31+$AB$8*F32) -> 0 | G38: =IF($B$8=0,0,$B$8*G6+$C$8*G7+$D$8*G8+$E$8*G9+$F$8*G10+$G$8*G11+$H$8*G12+$I$8*G13+$J$8*G14+$K$8*G15+$L$8*G16+$M$8*G17+$N$8*G18+$O$8*G19+$P$8*G20+$Q$8*G21+$R$8*G22+$S$8*G23+$T$8*G24+$U$8*G25+$V$8*G26+$W$8*G27+$X$8*G28+$Y$8*G29+$Z$8*G30+$AA$8*G31+$AB$8*G32) -> 0 | H38: =IF($B$8=0,0,$B$8*H6+$C$8*H7+$D$8*H8+$E$8*H9+$F$8*H10+$G$8*H11+$H$8*H12+$I$8*H13+$J$8*H14+$K$8*H15+$L$8*H16+$M$8*H17+$N$8*H18+$O$8*H19+$P$8*H20+$Q$8*H21+$R$8*H22+$S$8*H23+$T$8*H24+$U$8*H25+$V$8*H26+$W$8*H27+$X$8*H28+$Y$8*H29+$Z$8*H30+$AA$8*H31+$AB$8*H32) -> 0 | I38: =IF($B$8=0,0,$B$8*I6+$C$8*I7+$D$8*I8+$E$8*I9+$F$8*I10+$G$8*I11+$H$8*I12+$I$8*I13+$J$8*I14+$K$8*I15+$L$8*I16+$M$8*I17+$N$8*I18+$O$8*I19+$P$8*I20+$Q$8*I21+$R$8*I22+$S$8*I23+$T$8*I24+$U$8*I25+$V$8*I26+$W$8*I27+$X$8*I28+$Y$8*I29+$Z$8*I30+$AA$8*I31+$AB$8*I32) -> 0 | ... AB38: =IF($B$8=0,0,$B$8*AB6+$C$8*AB7+$D$8*AB8+$E$8*AB9+$F$8*AB10+$G$8*AB11+$H$8*AB12+$I$8*AB13+$J$8*AB14+$K$8*AB15+$L$8*AB16+$M$8*AB17+$N$8*AB18+$O$8*AB19+$P$8*AB20+$Q$8*AB21+$R$8*AB22+$S$8*AB23+$T$8*AB24+$U$8*AB25+$V$8*AB26+$W$8*AB27+$X$8*AB28+$Y$8*AB29+$Z$8*AB30+$AA$8*AB31+$AB$8*AB32) -> 0 | AC38: =SUM(B38:AB38) -> 0 | AD38: =AC38/$AC$63 -> 0
B39: =IF($B$9=0,0,$B$9*B6+$C$9*B7+$D$9*B8+$E$9*B9+$F$9*B10+$G$9*B11+$H$9*B12+$I$9*B13+$J$9*B14+$K$9*B15+$L$9*B16+$M$9*B17+$N$9*B18+$O$9*B19+$P$9*B20+$Q$9*B21+$R$9*B22+$S$9*B23+$T$9*B24+$U$9*B25+$V$9*B26+$W$9*B27+$X$9*B28+$Y$9*B29+$Z$9*B30+$AA$9*B31+$AB$9*B32) -> 0 | C39: =IF($B$9=0,0,$B$9*C6+$C$9*C7+$D$9*C8+$E$9*C9+$F$9*C10+$G$9*C11+$H$9*C12+$I$9*C13+$J$9*C14+$K$9*C15+$L$9*C16+$M$9*C17+$N$9*C18+$O$9*C19+$P$9*C20+$Q$9*C21+$R$9*C22+$S$9*C23+$T$9*C24+$U$9*C25+$V$9*C26+$W$9*C27+$X$9*C28+$Y$9*C29+$Z$9*C30+$AA$9*C31+$AB$9*C32) -> 0 | D39: =IF($B$9=0,0,$B$9*D6+$C$9*D7+$D$9*D8+$E$9*D9+$F$9*D10+$G$9*D11+$H$9*D12+$I$9*D13+$J$9*D14+$K$9*D15+$L$9*D16+$M$9*D17+$N$9*D18+$O$9*D19+$P$9*D20+$Q$9*D21+$R$9*D22+$S$9*D23+$T$9*D24+$U$9*D25+$V$9*D26+$W$9*D27+$X$9*D28+$Y$9*D29+$Z$9*D30+$AA$9*D31+$AB$9*D32) -> 0 | E39: =IF($B$9=0,0,$B$9*E6+$C$9*E7+$D$9*E8+$E$9*E9+$F$9*E10+$G$9*E11+$H$9*E12+$I$9*E13+$J$9*E14+$K$9*E15+$L$9*E16+$M$9*E17+$N$9*E18+$O$9*E19+$P$9*E20+$Q$9*E21+$R$9*E22+$S$9*E23+$T$9*E24+$U$9*E25+$V$9*E26+$W$9*E27+$X$9*E28+$Y$9*E29+$Z$9*E30+$AA$9*E31+$AB$9*E32) -> 0 | F39: =IF($B$9=0,0,$B$9*F6+$C$9*F7+$D$9*F8+$E$9*F9+$F$9*F10+$G$9*F11+$H$9*F12+$I$9*F13+$J$9*F14+$K$9*F15+$L$9*F16+$M$9*F17+$N$9*F18+$O$9*F19+$P$9*F20+$Q$9*F21+$R$9*F22+$S$9*F23+$T$9*F24+$U$9*F25+$V$9*F26+$W$9*F27+$X$9*F28+$Y$9*F29+$Z$9*F30+$AA$9*F31+$AB$9*F32) -> 0 | G39: =IF($B$9=0,0,$B$9*G6+$C$9*G7+$D$9*G8+$E$9*G9+$F$9*G10+$G$9*G11+$H$9*G12+$I$9*G13+$J$9*G14+$K$9*G15+$L$9*G16+$M$9*G17+$N$9*G18+$O$9*G19+$P$9*G20+$Q$9*G21+$R$9*G22+$S$9*G23+$T$9*G24+$U$9*G25+$V$9*G26+$W$9*G27+$X$9*G28+$Y$9*G29+$Z$9*G30+$AA$9*G31+$AB$9*G32) -> 0 | H39: =IF($B$9=0,0,$B$9*H6+$C$9*H7+$D$9*H8+$E$9*H9+$F$9*H10+$G$9*H11+$H$9*H12+$I$9*H13+$J$9*H14+$K$9*H15+$L$9*H16+$M$9*H17+$N$9*H18+$O$9*H19+$P$9*H20+$Q$9*H21+$R$9*H22+$S$9*H23+$T$9*H24+$U$9*H25+$V$9*H26+$W$9*H27+$X$9*H28+$Y$9*H29+$Z$9*H30+$AA$9*H31+$AB$9*H32) -> 0 | I39: =IF($B$9=0,0,$B$9*I6+$C$9*I7+$D$9*I8+$E$9*I9+$F$9*I10+$G$9*I11+$H$9*I12+$I$9*I13+$J$9*I14+$K$9*I15+$L$9*I16+$M$9*I17+$N$9*I18+$O$9*I19+$P$9*I20+$Q$9*I21+$R$9*I22+$S$9*I23+$T$9*I24+$U$9*I25+$V$9*I26+$W$9*I27+$X$9*I28+$Y$9*I29+$Z$9*I30+$AA$9*I31+$AB$9*I32) -> 0 | ... AB39: =IF($B$9=0,0,$B$9*AB6+$C$9*AB7+$D$9*AB8+$E$9*AB9+$F$9*AB10+$G$9*AB11+$H$9*AB12+$I$9*AB13+$J$9*AB14+$K$9*AB15+$L$9*AB16+$M$9*AB17+$N$9*AB18+$O$9*AB19+$P$9*AB20+$Q$9*AB21+$R$9*AB22+$S$9*AB23+$T$9*AB24+$U$9*AB25+$V$9*AB26+$W$9*AB27+$X$9*AB28+$Y$9*AB29+$Z$9*AB30+$AA$9*AB31+$AB$9*AB32) -> 0 | AC39: =SUM(B39:AB39) -> 0 | AD39: =AC39/$AC$63 -> 0
B40: =IF($B$10=0,0,$B$10*B6+$C$10*B7+$D$10*B8+$E$10*B9+$F$10*B10+$G$10*B11+$H$10*B12+$I$10*B13+$J$10*B14+$K$10*B15+$L$10*B16+$M$10*B17+$N$10*B18+$O$10*B19+$P$10*B20+$Q$10*B21+$R$10*B22+$S$10*B23+$T$10*B24+$U$10*B25+$V$10*B26+$W$10*B27+$X$10*B28+$Y$10*B29+$Z$10*B30+$AA$10*B31+$AB$10*B32) -> 0 | C40: =IF($B$10=0,0,$B$10*C6+$C$10*C7+$D$10*C8+$E$10*C9+$F$10*C10+$G$10*C11+$H$10*C12+$I$10*C13+$J$10*C14+$K$10*C15+$L$10*C16+$M$10*C17+$N$10*C18+$O$10*C19+$P$10*C20+$Q$10*C21+$R$10*C22+$S$10*C23+$T$10*C24+$U$10*C25+$V$10*C26+$W$10*C27+$X$10*C28+$Y$10*C29+$Z$10*C30+$AA$10*C31+$AB$10*C32) -> 0 | D40: =IF($B$10=0,0,$B$10*D6+$C$10*D7+$D$10*D8+$E$10*D9+$F$10*D10+$G$10*D11+$H$10*D12+$I$10*D13+$J$10*D14+$K$10*D15+$L$10*D16+$M$10*D17+$N$10*D18+$O$10*D19+$P$10*D20+$Q$10*D21+$R$10*D22+$S$10*D23+$T$10*D24+$U$10*D25+$V$10*D26+$W$10*D27+$X$10*D28+$Y$10*D29+$Z$10*D30+$AA$10*D31+$AB$10*D32) -> 0 | E40: =IF($B$10=0,0,$B$10*E6+$C$10*E7+$D$10*E8+$E$10*E9+$F$10*E10+$G$10*E11+$H$10*E12+$I$10*E13+$J$10*E14+$K$10*E15+$L$10*E16+$M$10*E17+$N$10*E18+$O$10*E19+$P$10*E20+$Q$10*E21+$R$10*E22+$S$10*E23+$T$10*E24+$U$10*E25+$V$10*E26+$W$10*E27+$X$10*E28+$Y$10*E29+$Z$10*E30+$AA$10*E31+$AB$10*E32) -> 0 | F40: =IF($B$10=0,0,$B$10*F6+$C$10*F7+$D$10*F8+$E$10*F9+$F$10*F10+$G$10*F11+$H$10*F12+$I$10*F13+$J$10*F14+$K$10*F15+$L$10*F16+$M$10*F17+$N$10*F18+$O$10*F19+$P$10*F20+$Q$10*F21+$R$10*F22+$S$10*F23+$T$10*F24+$U$10*F25+$V$10*F26+$W$10*F27+$X$10*F28+$Y$10*F29+$Z$10*F30+$AA$10*F31+$AB$10*F32) -> 0 | G40: =IF($B$10=0,0,$B$10*G6+$C$10*G7+$D$10*G8+$E$10*G9+$F$10*G10+$G$10*G11+$H$10*G12+$I$10*G13+$J$10*G14+$K$10*G15+$L$10*G16+$M$10*G17+$N$10*G18+$O$10*G19+$P$10*G20+$Q$10*G21+$R$10*G22+$S$10*G23+$T$10*G24+$U$10*G25+$V$10*G26+$W$10*G27+$X$10*G28+$Y$10*G29+$Z$10*G30+$AA$10*G31+$AB$10*G32) -> 0 | H40: =IF($B$10=0,0,$B$10*H6+$C$10*H7+$D$10*H8+$E$10*H9+$F$10*H10+$G$10*H11+$H$10*H12+$I$10*H13+$J$10*H14+$K$10*H15+$L$10*H16+$M$10*H17+$N$10*H18+$O$10*H19+$P$10*H20+$Q$10*H21+$R$10*H22+$S$10*H23+$T$10*H24+$U$10*H25+$V$10*H26+$W$10*H27+$X$10*H28+$Y$10*H29+$Z$10*H30+$AA$10*H31+$AB$10*H32) -> 0 | I40: =IF($B$10=0,0,$B$10*I6+$C$10*I7+$D$10*I8+$E$10*I9+$F$10*I10+$G$10*I11+$H$10*I12+$I$10*I13+$J$10*I14+$K$10*I15+$L$10*I16+$M$10*I17+$N$10*I18+$O$10*I19+$P$10*I20+$Q$10*I21+$R$10*I22+$S$10*I23+$T$10*I24+$U$10*I25+$V$10*I26+$W$10*I27+$X$10*I28+$Y$10*I29+$Z$10*I30+$AA$10*I31+$AB$10*I32) -> 0 | ... AB40: =IF($B$10=0,0,$B$10*AB6+$C$10*AB7+$D$10*AB8+$E$10*AB9+$F$10*AB10+$G$10*AB11+$H$10*AB12+$I$10*AB13+$J$10*AB14+$K$10*AB15+$L$10*AB16+$M$10*AB17+$N$10*AB18+$O$10*AB19+$P$10*AB20+$Q$10*AB21+$R$10*AB22+$S$10*AB23+$T$10*AB24+$U$10*AB25+$V$10*AB26+$W$10*AB27+$X$10*AB28+$Y$10*AB29+$Z$10*AB30+$AA$10*AB31+$AB$10*AB32) -> 0 | AC40: =SUM(B40:AB40) -> 0 | AD40: =AC40/$AC$63 -> 0
B41: =IF($B$11=0,0,$B$11*B6+$C$11*B7+$D$11*B8+$E$11*B9+$F$11*B10+$G$11*B11+$H$11*B12+$I$11*B13+$J$11*B14+$K$11*B15+$L$11*B16+$M$11*B17+$N$11*B18+$O$11*B19+$P$11*B20+$Q$11*B21+$R$11*B22+$S$11*B23+$T$11*B24+$U$11*B25+$V$11*B26+$W$11*B27+$X$11*B28+$Y$11*B29+$Z$11*B30+$AA$11*B31+$AB$11*B32) -> 0 | C41: =IF($B$11=0,0,$B$11*C6+$C$11*C7+$D$11*C8+$E$11*C9+$F$11*C10+$G$11*C11+$H$11*C12+$I$11*C13+$J$11*C14+$K$11*C15+$L$11*C16+$M$11*C17+$N$11*C18+$O$11*C19+$P$11*C20+$Q$11*C21+$R$11*C22+$S$11*C23+$T$11*C24+$U$11*C25+$V$11*C26+$W$11*C27+$X$11*C28+$Y$11*C29+$Z$11*C30+$AA$11*C31+$AB$11*C32) -> 0 | D41: =IF($B$11=0,0,$B$11*D6+$C$11*D7+$D$11*D8+$E$11*D9+$F$11*D10+$G$11*D11+$H$11*D12+$I$11*D13+$J$11*D14+$K$11*D15+$L$11*D16+$M$11*D17+$N$11*D18+$O$11*D19+$P$11*D20+$Q$11*D21+$R$11*D22+$S$11*D23+$T$11*D24+$U$11*D25+$V$11*D26+$W$11*D27+$X$11*D28+$Y$11*D29+$Z$11*D30+$AA$11*D31+$AB$11*D32) -> 0 | E41: =IF($B$11=0,0,$B$11*E6+$C$11*E7+$D$11*E8+$E$11*E9+$F$11*E10+$G$11*E11+$H$11*E12+$I$11*E13+$J$11*E14+$K$11*E15+$L$11*E16+$M$11*E17+$N$11*E18+$O$11*E19+$P$11*E20+$Q$11*E21+$R$11*E22+$S$11*E23+$T$11*E24+$U$11*E25+$V$11*E26+$W$11*E27+$X$11*E28+$Y$11*E29+$Z$11*E30+$AA$11*E31+$AB$11*E32) -> 0 | F41: =IF($B$11=0,0,$B$11*F6+$C$11*F7+$D$11*F8+$E$11*F9+$F$11*F10+$G$11*F11+$H$11*F12+$I$11*F13+$J$11*F14+$K$11*F15+$L$11*F16+$M$11*F17+$N$11*F18+$O$11*F19+$P$11*F20+$Q$11*F21+$R$11*F22+$S$11*F23+$T$11*F24+$U$11*F25+$V$11*F26+$W$11*F27+$X$11*F28+$Y$11*F29+$Z$11*F30+$AA$11*F31+$AB$11*F32) -> 0 | G41: =IF($B$11=0,0,$B$11*G6+$C$11*G7+$D$11*G8+$E$11*G9+$F$11*G10+$G$11*G11+$H$11*G12+$I$11*G13+$J$11*G14+$K$11*G15+$L$11*G16+$M$11*G17+$N$11*G18+$O$11*G19+$P$11*G20+$Q$11*G21+$R$11*G22+$S$11*G23+$T$11*G24+$U$11*G25+$V$11*G26+$W$11*G27+$X$11*G28+$Y$11*G29+$Z$11*G30+$AA$11*G31+$AB$11*G32) -> 0 | H41: =IF($B$11=0,0,$B$11*H6+$C$11*H7+$D$11*H8+$E$11*H9+$F$11*H10+$G$11*H11+$H$11*H12+$I$11*H13+$J$11*H14+$K$11*H15+$L$11*H16+$M$11*H17+$N$11*H18+$O$11*H19+$P$11*H20+$Q$11*H21+$R$11*H22+$S$11*H23+$T$11*H24+$U$11*H25+$V$11*H26+$W$11*H27+$X$11*H28+$Y$11*H29+$Z$11*H30+$AA$11*H31+$AB$11*H32) -> 0 | I41: =IF($B$11=0,0,$B$11*I6+$C$11*I7+$D$11*I8+$E$11*I9+$F$11*I10+$G$11*I11+$H$11*I12+$I$11*I13+$J$11*I14+$K$11*I15+$L$11*I16+$M$11*I17+$N$11*I18+$O$11*I19+$P$11*I20+$Q$11*I21+$R$11*I22+$S$11*I23+$T$11*I24+$U$11*I25+$V$11*I26+$W$11*I27+$X$11*I28+$Y$11*I29+$Z$11*I30+$AA$11*I31+$AB$11*I32) -> 0 | ... AB41: =IF($B$11=0,0,$B$11*AB6+$C$11*AB7+$D$11*AB8+$E$11*AB9+$F$11*AB10+$G$11*AB11+$H$11*AB12+$I$11*AB13+$J$11*AB14+$K$11*AB15+$L$11*AB16+$M$11*AB17+$N$11*AB18+$O$11*AB19+$P$11*AB20+$Q$11*AB21+$R$11*AB22+$S$11*AB23+$T$11*AB24+$U$11*AB25+$V$11*AB26+$W$11*AB27+$X$11*AB28+$Y$11*AB29+$Z$11*AB30+$AA$11*AB31+$AB$11*AB32) -> 0 | AC41: =SUM(B41:AB41) -> 0 | AD41: =AC41/$AC$63 -> 0
B42: =IF($B$12=0,0,$B$12*B6+$C$12*B7+$D$12*B8+$E$12*B9+$F$12*B10+$G$12*B11+$H$12*B12+$I$12*B13+$J$12*B14+$K$12*B15+$L$12*B16+$M$12*B17+$N$12*B18+$O$12*B19+$P$12*B20+$Q$12*B21+$R$12*B22+$S$12*B23+$T$12*B24+$U$12*B25+$V$12*B26+$W$12*B27+$X$12*B28+$Y$12*B29+$Z$12*B30+$AA$12*B31+$AB$12*B32) -> 0 | C42: =IF($B$12=0,0,$B$12*C6+$C$12*C7+$D$12*C8+$E$12*C9+$F$12*C10+$G$12*C11+$H$12*C12+$I$12*C13+$J$12*C14+$K$12*C15+$L$12*C16+$M$12*C17+$N$12*C18+$O$12*C19+$P$12*C20+$Q$12*C21+$R$12*C22+$S$12*C23+$T$12*C24+$U$12*C25+$V$12*C26+$W$12*C27+$X$12*C28+$Y$12*C29+$Z$12*C30+$AA$12*C31+$AB$12*C32) -> 0 | D42: =IF($B$12=0,0,$B$12*D6+$C$12*D7+$D$12*D8+$E$12*D9+$F$12*D10+$G$12*D11+$H$12*D12+$I$12*D13+$J$12*D14+$K$12*D15+$L$12*D16+$M$12*D17+$N$12*D18+$O$12*D19+$P$12*D20+$Q$12*D21+$R$12*D22+$S$12*D23+$T$12*D24+$U$12*D25+$V$12*D26+$W$12*D27+$X$12*D28+$Y$12*D29+$Z$12*D30+$AA$12*D31+$AB$12*D32) -> 0 | E42: =IF($B$12=0,0,$B$12*E6+$C$12*E7+$D$12*E8+$E$12*E9+$F$12*E10+$G$12*E11+$H$12*E12+$I$12*E13+$J$12*E14+$K$12*E15+$L$12*E16+$M$12*E17+$N$12*E18+$O$12*E19+$P$12*E20+$Q$12*E21+$R$12*E22+$S$12*E23+$T$12*E24+$U$12*E25+$V$12*E26+$W$12*E27+$X$12*E28+$Y$12*E29+$Z$12*E30+$AA$12*E31+$AB$12*E32) -> 0 | F42: =IF($B$12=0,0,$B$12*F6+$C$12*F7+$D$12*F8+$E$12*F9+$F$12*F10+$G$12*F11+$H$12*F12+$I$12*F13+$J$12*F14+$K$12*F15+$L$12*F16+$M$12*F17+$N$12*F18+$O$12*F19+$P$12*F20+$Q$12*F21+$R$12*F22+$S$12*F23+$T$12*F24+$U$12*F25+$V$12*F26+$W$12*F27+$X$12*F28+$Y$12*F29+$Z$12*F30+$AA$12*F31+$AB$12*F32) -> 0 | G42: =IF($B$12=0,0,$B$12*G6+$C$12*G7+$D$12*G8+$E$12*G9+$F$12*G10+$G$12*G11+$H$12*G12+$I$12*G13+$J$12*G14+$K$12*G15+$L$12*G16+$M$12*G17+$N$12*G18+$O$12*G19+$P$12*G20+$Q$12*G21+$R$12*G22+$S$12*G23+$T$12*G24+$U$12*G25+$V$12*G26+$W$12*G27+$X$12*G28+$Y$12*G29+$Z$12*G30+$AA$12*G31+$AB$12*G32) -> 0 | H42: =IF($B$12=0,0,$B$12*H6+$C$12*H7+$D$12*H8+$E$12*H9+$F$12*H10+$G$12*H11+$H$12*H12+$I$12*H13+$J$12*H14+$K$12*H15+$L$12*H16+$M$12*H17+$N$12*H18+$O$12*H19+$P$12*H20+$Q$12*H21+$R$12*H22+$S$12*H23+$T$12*H24+$U$12*H25+$V$12*H26+$W$12*H27+$X$12*H28+$Y$12*H29+$Z$12*H30+$AA$12*H31+$AB$12*H32) -> 0 | I42: =IF($B$12=0,0,$B$12*I6+$C$12*I7+$D$12*I8+$E$12*I9+$F$12*I10+$G$12*I11+$H$12*I12+$I$12*I13+$J$12*I14+$K$12*I15+$L$12*I16+$M$12*I17+$N$12*I18+$O$12*I19+$P$12*I20+$Q$12*I21+$R$12*I22+$S$12*I23+$T$12*I24+$U$12*I25+$V$12*I26+$W$12*I27+$X$12*I28+$Y$12*I29+$Z$12*I30+$AA$12*I31+$AB$12*I32) -> 0 | ... AB42: =IF($B$12=0,0,$B$12*AB6+$C$12*AB7+$D$12*AB8+$E$12*AB9+$F$12*AB10+$G$12*AB11+$H$12*AB12+$I$12*AB13+$J$12*AB14+$K$12*AB15+$L$12*AB16+$M$12*AB17+$N$12*AB18+$O$12*AB19+$P$12*AB20+$Q$12*AB21+$R$12*AB22+$S$12*AB23+$T$12*AB24+$U$12*AB25+$V$12*AB26+$W$12*AB27+$X$12*AB28+$Y$12*AB29+$Z$12*AB30+$AA$12*AB31+$AB$12*AB32) -> 0 | AC42: =SUM(B42:AB42) -> 0 | AD42: =AC42/$AC$63 -> 0
...

Sheet App domain specificity
A1: Evaluate alternatives: Use the same nine-point scale provided beside to compare the relative importance of each alternative (prioritized aspect) in the row to each alternative in the column (orange cells) concerning the "App domain specificity" criterion. Please only input a number in the cells with the column header if the header (-) keeps empty. Example Comparison: Ask yourself, "With respect to the criterion "App domain specificity," how much more do you prefer alternative (i.e., X "in the row" to alternative Y" in the column"? And assign a number from the scale. Continue by comparing each alternative (in the row) to all alternatives (in the columns) one by one concerning the "App domain specificity" criterion until all alternatives in the rows have been pairwise compared to the ones in the columns. Please Note (Less Important alternative): If you believe an alternative in the row is less important than one in the column, use the reciprocals of the nine-point scale, where 1 ("equally unimportant") to 1/9 ("extreme unimportance"). For example, if alternative X (in the row) is less important than alternative Y (in the column), you might assign a value like =1/3. | M1: Scale: 1: Equally important 2: Equally to moderately more important 3: Moderately more important 4: Moderately to strongly more important 5: Strongly more important 6: Strongly to very strongly more important 7: Very strongly more important 8: Very strongly to extremely more important 9: Extremely more important
A2: For more info, please visit: https://www.1000minds.com/decision-making/analytic-hierarchy-process-ahp
G4: App domain specificity(alternatives pairwise comparison matrix)
B5: {=IF(TRANSPOSE(A6:A32)=0,"-",TRANSPOSE(A6:A32))} -> #VALUE! | C5: - | D5: - | E5: - | F5: - | G5: - | H5: - | I5: - | J5: - | K5: - | L5: - | M5: - | N5: - | O5: - | P5: - | Q5: - | R5: - | S5: - | T5: - | U5: - | V5: - | W5: - | X5: - | Y5: - | Z5: - | AA5: - | AB5: -
A6: {=_xlfn._xlws.FILTER('AHP(Structure the hierarchy)'!B6:B33, 'AHP(Structure the hierarchy)'!B6:B33<>"")} -> #VALUE! | B6: 1
B7: =IF(C6=0,0,1/C6) -> 0 | C7: 1
B8: =IF(D6=0,0,1/D6) -> 0 | C8: =IF(D7=0,0,1/D7) -> 0 | D8: 1
B9: =IF(E6=0,0,1/E6) -> 0 | C9: =IF(E7=0,0,1/E7) -> 0 | D9: =IF(E8=0,0,1/E8) -> 0 | E9: 1
B10: =IF(F6=0,0,1/F6) -> 0 | C10: =IF(F7=0,0,1/F7) -> 0 | D10: =IF(F8=0,0,1/F8) -> 0 | E10: =IF(F9=0,0,1/F9) -> 0 | F10: 1
B11: =IF(G6=0,0,1/G6) -> 0 | C11: =IF(G7=0,0,1/G7) -> 0 | D11: =IF(G8=0,0,1/G8) -> 0 | E11: =IF(G9=0,0,1/G9) -> 0 | F11: =IF(G10=0,0,1/G10) -> 0 | G11: 1
B12: =IF(H6=0,0,1/H6) -> 0 | C12: =IF(H7=0,0,1/H7) -> 0 | D12: =IF(H8=0,0,1/H8) -> 0 | E12: =IF(H9=0,0,1/H9) -> 0 | F12: =IF(H10=0,0,1/H10) -> 0 | G12: =IF(H11=0,0,1/H11) -> 0 | H12: 1
B13: =IF(I6=0,0,1/I6) -> 0 | C13: =IF(I7=0,0,1/I7) -> 0 | D13: =IF(I8=0,0,1/I8) -> 0 | E13: =IF(I9=0,0,1/I9) -> 0 | F13: =IF(I10=0,0,1/I10) -> 0 | G13: =IF(I11=0,0,1/I11) -> 0 | H13: =IF(I12=0,0,1/I12) -> 0 | I13: 1
B14: =IF(J6=0,0,1/J6) -> 0 | C14: =IF(J7=0,0,1/J7) -> 0 | D14: =IF(J8=0,0,1/J8) -> 0 | E14: =IF(J9=0,0,1/J9) -> 0 | F14: =IF(J10=0,0,1/J10) -> 0 | G14: =IF(J11=0,0,1/J11) -> 0 | H14: =IF(J12=0,0,1/J12) -> 0 | I14: =IF(J13=0,0,1/J13) -> 0 | J14: 1
B15: =IF(K6=0,0,1/K6) -> 0 | C15: =IF(K7=0,0,1/K7) -> 0 | D15: =IF(K8=0,0,1/K8) -> 0 | E15: =IF(K9=0,0,1/K9) -> 0 | F15: =IF(K10=0,0,1/K10) -> 0 | G15: =IF(K11=0,0,1/K11) -> 0 | H15: =IF(K12=0,0,1/K12) -> 0 | I15: =IF(K13=0,0,1/K13) -> 0 | J15: =IF(K14=0,0,1/K14) -> 0 | K15: 1
B16: =IF(L6=0,0,1/L6) -> 0 | C16: =IF(L7=0,0,1/L7) -> 0 | D16: =IF(L8=0,0,1/L8) -> 0 | E16: =IF(L9=0,0,1/L9) -> 0 | F16: =IF(L10=0,0,1/L10) -> 0 | G16: =IF(L11=0,0,1/L11) -> 0 | H16: =IF(L12=0,0,1/L12) -> 0 | I16: =IF(L13=0,0,1/L13) -> 0 | J16: =IF(L14=0,0,1/L14) -> 0 | K16: =IF(L15=0,0,1/L15) -> 0 | L16: 1
B17: =IF(M6=0,0,1/M6) -> 0 | C17: =IF(M7=0,0,1/M7) -> 0 | D17: =IF(M8=0,0,1/M8) -> 0 | E17: =IF(M9=0,0,1/M9) -> 0 | F17: =IF(M10=0,0,1/M10) -> 0 | G17: =IF(M11=0,0,1/M11) -> 0 | H17: =IF(M12=0,0,1/M12) -> 0 | I17: =IF(M13=0,0,1/M13) -> 0 | J17: =IF(M14=0,0,1/M14) -> 0 | K17: =IF(M15=0,0,1/M15) -> 0 | L17: =IF(M16=0,0,1/M16) -> 0 | M17: 1
B18: =IF(N6=0,0,1/N6) -> 0 | C18: =IF(N7=0,0,1/N7) -> 0 | D18: =IF(N8=0,0,1/N8) -> 0 | E18: =IF(N9=0,0,1/N9) -> 0 | F18: =IF(N10=0,0,1/N10) -> 0 | G18: =IF(N11=0,0,1/N11) -> 0 | H18: =IF(N12=0,0,1/N12) -> 0 | I18: =IF(N13=0,0,1/N13) -> 0 | J18: =IF(N14=0,0,1/N14) -> 0 | K18: =IF(N15=0,0,1/N15) -> 0 | L18: =IF(N16=0,0,1/N16) -> 0 | M18: =IF(N17=0,0,1/N17) -> 0 | N18: 1
B19: =IF(O6=0,0,1/O6) -> 0 | C19: =IF(O7=0,0,1/O7) -> 0 | D19: =IF(O8=0,0,1/O8) -> 0 | E19: =IF(O9=0,0,1/O9) -> 0 | F19: =IF(O10=0,0,1/O10) -> 0 | G19: =IF(O11=0,0,1/O11) -> 0 | H19: =IF(O12=0,0,1/O12) -> 0 | I19: =IF(O13=0,0,1/O13) -> 0 | J19: =IF(O14=0,0,1/O14) -> 0 | K19: =IF(O15=0,0,1/O15) -> 0 | L19: =IF(O16=0,0,1/O16) -> 0 | M19: =IF(O17=0,0,1/O17) -> 0 | N19: =IF(O18=0,0,1/O18) -> 0 | O19: 1
B20: =IF(P6=0,0,1/P6) -> 0 | C20: =IF(P7=0,0,1/P7) -> 0 | D20: =IF(P8=0,0,1/P8) -> 0 | E20: =IF(P9=0,0,1/P9) -> 0 | F20: =IF(P10=0,0,1/P10) -> 0 | G20: =IF(P11=0,0,1/P11) -> 0 | H20: =IF(P12=0,0,1/P12) -> 0 | I20: =IF(P13=0,0,1/P13) -> 0 | J20: =IF(P14=0,0,1/P14) -> 0 | K20: =IF(P15=0,0,1/P15) -> 0 | L20: =IF(P16=0,0,1/P16) -> 0 | M20: =IF(P17=0,0,1/P17) -> 0 | N20: =IF(P18=0,0,1/P18) -> 0 | O20: =IF(P19=0,0,1/P19) -> 0 | P20: 1
B21: =IF(Q6=0,0,1/Q6) -> 0 | C21: =IF(Q7=0,0,1/Q7) -> 0 | D21: =IF(Q8=0,0,1/Q8) -> 0 | E21: =IF(Q9=0,0,1/Q9) -> 0 | F21: =IF(Q10=0,0,1/Q10) -> 0 | G21: =IF(Q11=0,0,1/Q11) -> 0 | H21: =IF(Q12=0,0,1/Q12) -> 0 | I21: =IF(Q13=0,0,1/Q13) -> 0 | J21: =IF(Q14=0,0,1/Q14) -> 0 | K21: =IF(Q15=0,0,1/Q15) -> 0 | L21: =IF(Q16=0,0,1/Q16) -> 0 | M21: =IF(Q17=0,0,1/Q17) -> 0 | N21: =IF(Q18=0,0,1/Q18) -> 0 | O21: =IF(Q19=0,0,1/Q19) -> 0 | P21: =IF(Q20=0,0,1/Q20) -> 0 | Q21: 1
B22: =IF(R6=0,0,1/R6) -> 0 | C22: =IF(R7=0,0,1/R7) -> 0 | D22: =IF(R8=0,0,1/R8) -> 0 | E22: =IF(R9=0,0,1/R9) -> 0 | F22: =IF(R10=0,0,1/R10) -> 0 | G22: =IF(R11=0,0,1/R11) -> 0 | H22: =IF(R12=0,0,1/R12) -> 0 | I22: =IF(R13=0,0,1/R13) -> 0 | J22: =IF(R14=0,0,1/R14) -> 0 | K22: =IF(R15=0,0,1/R15) -> 0 | L22: =IF(R16=0,0,1/R16) -> 0 | M22: =IF(R17=0,0,1/R17) -> 0 | N22: =IF(R18=0,0,1/R18) -> 0 | O22: =IF(R19=0,0,1/R19) -> 0 | P22: =IF(R20=0,0,1/R20) -> 0 | Q22: =IF(R21=0,0,1/R21) -> 0 | R22: 1
B23: =IF(S6=0,0,1/S6) -> 0 | C23: =IF(S7=0,0,1/S7) -> 0 | D23: =IF(S8=0,0,1/S8) -> 0 | E23: =IF(S9=0,0,1/S9) -> 0 | F23: =IF(S10=0,0,1/S10) -> 0 | G23: =IF(S11=0,0,1/S11) -> 0 | H23: =IF(S12=0,0,1/S12) -> 0 | I23: =IF(S13=0,0,1/S13) -> 0 | J23: =IF(S14=0,0,1/S14) -> 0 | K23: =IF(S15=0,0,1/S15) -> 0 | L23: =IF(S16=0,0,1/S16) -> 0 | M23: =IF(S17=0,0,1/S17) -> 0 | N23: =IF(S18=0,0,1/S18) -> 0 | O23: =IF(S19=0,0,1/S19) -> 0 | P23: =IF(S20=0,0,1/S20) -> 0 | Q23: =IF(S21=0,0,1/S21) -> 0 | R23: =IF(S22=0,0,1/S22) -> 0 | S23: 1
B24: =IF(T6=0,0,1/T6) -> 0 | C24: =IF(T7=0,0,1/T7) -> 0 | D24: =IF(T8=0,0,1/T8) -> 0 | E24: =IF(T9=0,0,1/T9) -> 0 | F24: =IF(T10=0,0,1/T10) -> 0 | G24: =IF(T11=0,0,1/T11) -> 0 | H24: =IF(T12=0,0,1/T12) -> 0 | I24: =IF(T13=0,0,1/T13) -> 0 | J24: =IF(T14=0,0,1/T14) -> 0 | K24: =IF(T15=0,0,1/T15) -> 0 | L24: =IF(T16=0,0,1/T16) -> 0 | M24: =IF(T17=0,0,1/T17) -> 0 | N24: =IF(T18=0,0,1/T18) -> 0 | O24: =IF(T19=0,0,1/T19) -> 0 | P24: =IF(T20=0,0,1/T20) -> 0 | Q24: =IF(T21=0,0,1/T21) -> 0 | R24: =IF(T22=0,0,1/T22) -> 0 | S24: =IF(T23=0,0,1/T23) -> 0 | T24: 1
